Workbook

Sheet Legend
B3: ID Prefix | C3: Category
B4: SEC | C4: Security
B5: PERF | C5: Performance
B6: DB | C6: Dashboard Backend
B7: MB | C7: Mobile Backend
B8: DF | C8: Dashboard Frontend
B9: MP | C9: Mobile Passenger
B10: MD | C10: Mobile Driver
B11: SA | C11: Sharapp
B12: CR | C12: Cross Repos
B13: NTH | C13: Nice to Have

Sheet Old
A1: # | B1: Milestone | C1: Scope | D1: Description | E1: Estimation
A2: 1 | B2: Security Fixes | C2: Security | D2: Fix Backend Security Issues Move frontend/app security access to backend
A3: 2 | B3: AWS Fixes | C3: AWS | D3: Reduce AWS Spend
A4: 3 | B4: Critical performance Critical Bugs | C4: Dashboard Mobile backend Mobile Driver Sharapp | D4: Improve performance fix customer facing issues Add logging
A5: 4 | B5: High Performance High Bugs
A6: 5 | B6: Critical/High UI/UX | C6: UI/UX Visual Design | D6: Improve user experience with regards to views
A7: 6 | B7: Medium/Low Performance Medium/Low bugs
A8: 7 | B8: Medium/Low UI/UX | C8: UI/UX Visual Design | D8: Finalize UI/U improvements
A9: 8 | B9: Functionality

Sheet WP
B3: # | C3: Work Package | D3: Issue Count | E3: Duration | F3: Sub-Work Packages / Deliverables
B4: =ROW() - ROW(Table3[[#Headers],['#]]) -> 1 | C4: Critical Security & Infrastructure | D4: 25 | F4: 1.1- Fix all hardcoded credentials and clean Git history 1.2- Rotate all API keys and secrets 1.3- Configure CORS properly 1.4- Implement basic rate limiting 1.5- Perform AWS security hardening (IAM policies, security groups)
B5: =ROW() - ROW(Table3[[#Headers],['#]]) -> 2 | C5: Framework Upgrades & Core Performance | F5: 2.1- Upgrade Django framework (both backends) 2.2- Fix critical N+1 queries 2.3- Optimize database performance and indexing 2.4- Conduct database migrations 2.5- Implement pagination improvements
B6: =ROW() - ROW(Table3[[#Headers],['#]]) -> 3 | C6: Authentication & Token Management | F6: 3.1- Implement token lifecycle management (access + refresh) 3.2- Use httpOnly cookies for session security 3.3- Add CSRF protection 3.4- Integrate multi-factor authentication (MFA) 3.5- Test and validate all authentication flows
B7: =ROW() - ROW(Table3[[#Headers],['#]]) -> 4 | C7: Performance Optimization | F7: 4.1- Resolve remaining N+1 queries 4.2- Optimize aggregation pipelines 4.3- Add caching (Redis / in-memory) 4.4- Conduct load testing and profiling 4.5- Implement performance monitoring dashboards
B8: =ROW() - ROW(Table3[[#Headers],['#]]) -> 5 | C8: UI/UX & Mobile | F8: 5.1- Implement UI/UX improvements (Sharapp, dashboard, mobile apps) 5.2- Fix mobile app bugs 5.3- Ensure responsive design 5.4- Perform cross-browser and device testing
B9: =ROW() - ROW(Table3[[#Headers],['#]]) -> 6 | C9: Bugs, Code Quality & Finalizing AWS | F9: 6.1- Perform code quality review and refactoring 6.2- Fix remaining bugs 6.3- Optimize AWS resources (EC2, EBS, RDS) 6.4- Conduct final system testing and validation 6.5- Prepare documentation

Sheet Planning
A3: Sub-WP | B3: ID | C3: Issue | D3: Estimate (WD) | E3: Milestone
A4: WP1: Critical Security & Infrastructure
A5: 1.1 | B5: SEC-001 | C5: Hardcoded MongoDB Credentials
B6: SEC-004 | C6: Google Maps API Key Hardcoded
B7: SEC-005 | C7: Permissive CORS Configuration
B8: SEC-017 | C8: No Secrets Management Solution
B9: SEC-023 | C9: Weak Password Policy
B10: AWS-010 | C10: Security risk: port 22 (SSH) is open to the world on most EC2 instances.
B11: AWS-019 | C11: CloudTrail management events disabled
B12: AWS-029 | C12: Application Load Balancer Security Group Misconfiguration
A13: 1.2 | B13: SEC-002 | C13: Exposed AWS Access Keys
B14: SEC-011 | C14: Missing Security Headers
B15: SEC-012 | C15: Insufficient Input Validation
B16: SEC-014 | C16: Debug Mode Enabled
B17: SEC-015 | C17: Insufficient Logging and Monitoring
B18: SEC-016 | C18: No Web Application Firewall
B19: AWS-022 | C19: MFA and key rotation gaps in IAM users
A20: 1.3 | B20: SEC-018 | C20: No API Versioning
B21: SEC-019 | C21: No SSL Certificate Pinning
B22: SEC-020 | C22: No Root/Jailbreak Detection
B23: SEC-021 | C23: Insufficient File Upload Validation
B24: SEC-025 | C24: No Database Query Optimization
B25: SEC-026 | C25: No Content Security for Stored Files
B26: AWS-026 | C26: Application Load Balancers serving HTTP health checks
A27: 1.4 | B27: SEC-006 | C27: Ineffective Rate Limiting
B28: SEC-024 | C28: No Request Size Limits
A29: 1.5 | B29: AWS-020 | C29: External resource sharing via IAM Access Analyzer findings
B30: AWS-028 | C30: Security Groups – Unrestricted Access
A31: WP2: Framework Upgrades & Core Performance
A32: 2.1 | B32: SEC-010 | C32: Outdated Django Framework
B33: PERF-DB-002 | C33: Missing Database Connection Pooling
A34: 2.2 | B34: PERF-DB-003 | C34: N+1 Query in Account Serializer
B35: PERF-DB-010 | C35: Missing Query Optimization (only/defer)
B36: PERF-DB-011 | C36: Inefficient Nested Loops Over QuerySets
B37: PERF-MB-003 | C37: N+1 in Driver Transactions
A38: 2.4 | B38: PERF-DB-013 | C38: Missing Indexes on Frequently Queried Fields
B39: PERF-MB-002 | C39: Missing Database Indexes
A40: 2.5 | B40: PERF-DB-004 | C40: Massive Aggregation Without Pagination
B41: PERF-DB-005 | C41: Inefficient Driver Pagination
B42: PERF-MP-011 | C42: No Pagination in Trip History

Sheet Summary
B1: JTNY Security Audit - Complete Analysis
B2: Critical | C2: High | D2: Medium | E2: Low | F2: Total
B3: =COUNTIFS(Security_Analysis!A:A,"*SEC*",Security_Analysis!B:B,"CRITICAL") -> 6 | C3: =COUNTIFS(Security_Analysis!A:A,"*SEC*",Security_Analysis!B:B,"HIGH") -> 11 | D3: =COUNTIFS(Security_Analysis!A:A,"*SEC*",Security_Analysis!B:B,"MEDIUM") -> 9 | E3: =COUNTIFS(Security_Analysis!A:A,"*SEC*",Security_Analysis!B:B,"LOW") -> 0 | F3: =SUM(B3:E3) -> 26
B5: JTNY Performance Audit - Complete Analysis
B6: Repository | C6: Critical | D6: High | E6: Medium | F6: Low | G6: Total
B7: DB | C7: =COUNTIFS(Performance_Analysis!A:A,"*PERF-DB*",Performance_Analysis!B:B,"CRITICAL") -> 6 | D7: =COUNTIFS(Performance_Analysis!A:A,"*PERF-DB*",Performance_Analysis!B:B,"HIGH") -> 9 | E7: =COUNTIFS(Performance_Analysis!A:A,"*PERF-DB*",Performance_Analysis!B:B,"MEDIUM") -> 12 | F7: =COUNTIFS(Performance_Analysis!A:A,"*PERF-DB*",Performance_Analysis!B:B,"LOW") -> 4 | G7: =SUM(C7:F7) -> 31
B8: MB | C8: =COUNTIFS(Performance_Analysis!A:A,"*PERF-MB*",Performance_Analysis!B:B,"CRITICAL") -> 2 | D8: =COUNTIFS(Performance_Analysis!A:A,"*PERF-MB*",Performance_Analysis!B:B,"HIGH") -> 7 | E8: =COUNTIFS(Performance_Analysis!A:A,"*PERF-MB*",Performance_Analysis!B:B,"MEDIUM") -> 6 | F8: =COUNTIFS(Performance_Analysis!A:A,"*PERF-MB*",Performance_Analysis!B:B,"LOW") -> 0 | G8: =SUM(C8:F8) -> 15
B9: DF | C9: =COUNTIFS(Performance_Analysis!A:A,"*PERF-DF*",Performance_Analysis!B:B,"CRITICAL") -> 2 | D9: =COUNTIFS(Performance_Analysis!A:A,"*PERF-DF*",Performance_Analysis!B:B,"HIGH") -> 8 | E9: =COUNTIFS(Performance_Analysis!A:A,"*PERF-DF*",Performance_Analysis!B:B,"MEDIUM") -> 4 | F9: =COUNTIFS(Performance_Analysis!A:A,"*PERF-DF*",Performance_Analysis!B:B,"LOW") -> 1 | G9: =SUM(C9:F9) -> 15
B10: MP | C10: =COUNTIFS(Performance_Analysis!A:A,"*PERF-MP*",Performance_Analysis!B:B,"CRITICAL") -> 1 | D10: =COUNTIFS(Performance_Analysis!A:A,"*PERF-MP*",Performance_Analysis!B:B,"HIGH") -> 7 | E10: =COUNTIFS(Performance_Analysis!A:A,"*PERF-MP*",Performance_Analysis!B:B,"MEDIUM") -> 6 | F10: =COUNTIFS(Performance_Analysis!A:A,"*PERF-MP*",Performance_Analysis!B:B,"LOW") -> 0 | G10: =SUM(C10:F10) -> 14
B11: MD | C11: =COUNTIFS(Performance_Analysis!A:A,"*PERF-MD*",Performance_Analysis!B:B,"CRITICAL") -> 2 | D11: =COUNTIFS(Performance_Analysis!A:A,"*PERF-MD*",Performance_Analysis!B:B,"HIGH") -> 7 | E11: =COUNTIFS(Performance_Analysis!A:A,"*PERF-MD*",Performance_Analysis!B:B,"MEDIUM") -> 5 | F11: =COUNTIFS(Performance_Analysis!A:A,"*PERF-MD*",Performance_Analysis!B:B,"LOW") -> 1 | G11: =SUM(C11:F11) -> 15
B12: SA | C12: =COUNTIFS(Performance_Analysis!A:A,"*PERF-SA*",Performance_Analysis!B:B,"CRITICAL") -> 2 | D12: =COUNTIFS(Performance_Analysis!A:A,"*PERF-SA*",Performance_Analysis!B:B,"HIGH") -> 4 | E12: =COUNTIFS(Performance_Analysis!A:A,"*PERF-SA*",Performance_Analysis!B:B,"MEDIUM") -> 3 | F12: =COUNTIFS(Performance_Analysis!A:A,"*PERF-SA*",Performance_Analysis!B:B,"LOW") -> 3 | G12: =SUM(C12:F12) -> 12
B13: CR | C13: =COUNTIFS(Performance_Analysis!A:A,"*PERF-CR*",Performance_Analysis!B:B,"CRITICAL") -> 2 | D13: =COUNTIFS(Performance_Analysis!A:A,"*PERF-CR*",Performance_Analysis!B:B,"HIGH") -> 2 | E13: =COUNTIFS(Performance_Analysis!A:A,"*PERF-CR*",Performance_Analysis!B:B,"MEDIUM") -> 2 | F13: =COUNTIFS(Performance_Analysis!A:A,"*PERF-CR*",Performance_Analysis!B:B,"LOW") -> 1 | G13: =SUM(C13:F13) -> 7
B14: NTH | C14: =COUNTIFS(Performance_Analysis!A:A,"*PERF-NTH*",Performance_Analysis!B:B,"CRITICAL") -> 0 | D14: =COUNTIFS(Performance_Analysis!A:A,"*PERF-NTH*",Performance_Analysis!B:B,"HIGH") -> 0 | E14: =COUNTIFS(Performance_Analysis!A:A,"*PERF-NTH*",Performance_Analysis!B:B,"MEDIUM") -> 0 | F14: =COUNTIFS(Performance_Analysis!A:A,"*PERF-NTH*",Performance_Analysis!B:B,"LOW") -> 10 | G14: =SUM(C14:F14) -> 10
B15: TOTAL | C15: =SUM(C7:C14) -> 17 | D15: =SUM(D7:D14) -> 44 | E15: =SUM(E7:E14) -> 38 | F15: =SUM(F7:F14) -> 20 | G15: =SUM(C15:F15) -> 119
B17: JTNY UI/UX Audit - Complete Analysis
B18: Repository | C18: Critical | D18: High | E18: Medium | F18: Low | G18: Total
B19: SA | C19: =COUNTIFS('UI-UX_Analysis'!A:A,"*UIUX-SA*",'UI-UX_Analysis'!B:B,"CRITICAL") -> 1 | D19: =COUNTIFS('UI-UX_Analysis'!A:A,"*UIUX-SA*",'UI-UX_Analysis'!B:B,"HIGH") -> 7 | E19: =COUNTIFS('UI-UX_Analysis'!A:A,"*UIUX-SA*",'UI-UX_Analysis'!B:B,"MEDIUM") -> 9 | F19: =COUNTIFS('UI-UX_Analysis'!A:A,"*UIUX-SA*",'UI-UX_Analysis'!B:B,"LOW") -> 9 | G19: =SUM(C19:F19) -> 26
B20: MD | C20: =COUNTIFS('UI-UX_Analysis'!A:A,"*UIUX-MD*",'UI-UX_Analysis'!B:B,"CRITICAL") -> 1 | D20: =COUNTIFS('UI-UX_Analysis'!A:A,"*UIUX-MD*",'UI-UX_Analysis'!B:B,"HIGH") -> 21 | E20: =COUNTIFS('UI-UX_Analysis'!A:A,"*UIUX-MD*",'UI-UX_Analysis'!B:B,"MEDIUM") -> 11 | F20: =COUNTIFS('UI-UX_Analysis'!A:A,"*UIUX-MD*",'UI-UX_Analysis'!B:B,"LOW") -> 5 | G20: =SUM(C20:F20) -> 38
B21: MP | C21: =COUNTIFS('UI-UX_Analysis'!A:A,"*UIUX-MP*",'UI-UX_Analysis'!B:B,"CRITICAL") -> 2 | D21: =COUNTIFS('UI-UX_Analysis'!A:A,"*UIUX-MP*",'UI-UX_Analysis'!B:B,"HIGH") -> 8 | E21: =COUNTIFS('UI-UX_Analysis'!A:A,"*UIUX-MP*",'UI-UX_Analysis'!B:B,"MEDIUM") -> 8 | F21: =COUNTIFS('UI-UX_Analysis'!A:A,"*UIUX-MP*",'UI-UX_Analysis'!B:B,"LOW") -> 19 | G21: =SUM(C21:F21) -> 37
B22: DF | C22: =COUNTIFS('UI-UX_Analysis'!A:A,"*UIUX-DF*",'UI-UX_Analysis'!B:B,"CRITICAL") -> 1 | D22: =COUNTIFS('UI-UX_Analysis'!A:A,"*UIUX-DF*",'UI-UX_Analysis'!B:B,"HIGH") -> 12 | E22: =COUNTIFS('UI-UX_Analysis'!A:A,"*UIUX-DF*",'UI-UX_Analysis'!B:B,"MEDIUM") -> 20 | F22: =COUNTIFS('UI-UX_Analysis'!A:A,"*UIUX-DF*",'UI-UX_Analysis'!B:B,"LOW") -> 6 | G22: =SUM(C22:F22) -> 39
B23: DB | C23: =COUNTIFS('UI-UX_Analysis'!A:A,"*UIUX-DB*",'UI-UX_Analysis'!B:B,"CRITICAL") -> 0 | D23: =COUNTIFS('UI-UX_Analysis'!A:A,"*UIUX-DB*",'UI-UX_Analysis'!B:B,"HIGH") -> 6 | E23: =COUNTIFS('UI-UX_Analysis'!A:A,"*UIUX-DB*",'UI-UX_Analysis'!B:B,"MEDIUM") -> 14 | F23: =COUNTIFS('UI-UX_Analysis'!A:A,"*UIUX-DB*",'UI-UX_Analysis'!B:B,"LOW") -> 6 | G23: =SUM(C23:F23) -> 26
B24: MB | C24: =COUNTIFS('UI-UX_Analysis'!A:A,"*UIUX-MB*",'UI-UX_Analysis'!B:B,"CRITICAL") -> 0 | D24: =COUNTIFS('UI-UX_Analysis'!A:A,"*UIUX-MB*",'UI-UX_Analysis'!B:B,"HIGH") -> 8 | E24: =COUNTIFS('UI-UX_Analysis'!A:A,"*UIUX-MB*",'UI-UX_Analysis'!B:B,"MEDIUM") -> 14 | F24: =COUNTIFS('UI-UX_Analysis'!A:A,"*UIUX-MB*",'UI-UX_Analysis'!B:B,"LOW") -> 4 | G24: =SUM(C24:F24) -> 26
B25: Total | C25: =SUM(C19:C23) -> 5 | D25: =SUM(D19:D23) -> 54 | E25: =SUM(E19:E23) -> 62 | F25: =SUM(F19:F23) -> 45 | G25: =SUM(C25:F25) -> 166
B27: JTNY Bugs & Code Quality Audit - Complete Analysis
B28: Repository | C28: Critical | D28: High | E28: Medium | F28: Low | G28: Total
B29: SA | C29: =COUNTIFS('Bugs&CodeQuality_Analysis'!A:A,"*BUGS-SA*",'Bugs&CodeQuality_Analysis'!B:B,"CRITICAL") -> 5 | D29: =COUNTIFS('Bugs&CodeQuality_Analysis'!A:A,"*BUGS-SA*",'Bugs&CodeQuality_Analysis'!B:B,"HIGH") -> 4 | E29: =COUNTIFS('Bugs&CodeQuality_Analysis'!A:A,"*BUGS-SA*",'Bugs&CodeQuality_Analysis'!B:B,"MEDIUM") -> 5 | F29: =COUNTIFS('Bugs&CodeQuality_Analysis'!A:A,"*BUGS-SA*",'Bugs&CodeQuality_Analysis'!B:B,"LOW") -> 11 | G29: =SUM(C29:F29) -> 25
B30: MP | C30: =COUNTIFS('Bugs&CodeQuality_Analysis'!A:A,"*BUGS-MP*",'Bugs&CodeQuality_Analysis'!B:B,"CRITICAL") -> 3 | D30: =COUNTIFS('Bugs&CodeQuality_Analysis'!A:A,"*BUGS-MP*",'Bugs&CodeQuality_Analysis'!B:B,"HIGH") -> 10 | E30: =COUNTIFS('Bugs&CodeQuality_Analysis'!A:A,"*BUGS-MP*",'Bugs&CodeQuality_Analysis'!B:B,"MEDIUM") -> 13 | F30: =COUNTIFS('Bugs&CodeQuality_Analysis'!A:A,"*BUGS-MP*",'Bugs&CodeQuality_Analysis'!B:B,"LOW") -> 10 | G30: =SUM(C30:F30) -> 36
B31: MD | C31: =COUNTIFS('Bugs&CodeQuality_Analysis'!A:A,"*BUGS-MD*",'Bugs&CodeQuality_Analysis'!B:B,"CRITICAL") -> 1 | D31: =COUNTIFS('Bugs&CodeQuality_Analysis'!A:A,"*BUGS-MD*",'Bugs&CodeQuality_Analysis'!B:B,"HIGH") -> 15 | E31: =COUNTIFS('Bugs&CodeQuality_Analysis'!A:A,"*BUGS-MD*",'Bugs&CodeQuality_Analysis'!B:B,"MEDIUM") -> 4 | F31: =COUNTIFS('Bugs&CodeQuality_Analysis'!A:A,"*BUGS-MD*",'Bugs&CodeQuality_Analysis'!B:B,"LOW") -> 0 | G31: =SUM(C31:F31) -> 20
B32: DF | C32: =COUNTIFS('Bugs&CodeQuality_Analysis'!A:A,"*BUGS-DF*",'Bugs&CodeQuality_Analysis'!B:B,"CRITICAL") -> 0 | D32: =COUNTIFS('Bugs&CodeQuality_Analysis'!A:A,"*BUGS-DF*",'Bugs&CodeQuality_Analysis'!B:B,"HIGH") -> 4 | E32: =COUNTIFS('Bugs&CodeQuality_Analysis'!A:A,"*BUGS-DF*",'Bugs&CodeQuality_Analysis'!B:B,"MEDIUM") -> 14 | F32: =COUNTIFS('Bugs&CodeQuality_Analysis'!A:A,"*BUGS-DF*",'Bugs&CodeQuality_Analysis'!B:B,"LOW") -> 11 | G32: =SUM(C32:F32) -> 29
B33: DB | C33: =COUNTIFS('Bugs&CodeQuality_Analysis'!A:A,"*BUGS-DB*",'Bugs&CodeQuality_Analysis'!B:B,"CRITICAL") -> 2 | D33: =COUNTIFS('Bugs&CodeQuality_Analysis'!A:A,"*BUGS-DB*",'Bugs&CodeQuality_Analysis'!B:B,"HIGH") -> 6 | E33: =COUNTIFS('Bugs&CodeQuality_Analysis'!A:A,"*BUGS-DB*",'Bugs&CodeQuality_Analysis'!B:B,"MEDIUM") -> 5 | F33: =COUNTIFS('Bugs&CodeQuality_Analysis'!A:A,"*BUGS-DB*",'Bugs&CodeQuality_Analysis'!B:B,"LOW") -> 2 | G33: =SUM(C33:F33) -> 15
B34: MB | C34: =COUNTIFS('Bugs&CodeQuality_Analysis'!A:A,"*BUGS-MB*",'Bugs&CodeQuality_Analysis'!B:B,"CRITICAL") -> 1 | D34: =COUNTIFS('Bugs&CodeQuality_Analysis'!A:A,"*BUGS-MB*",'Bugs&CodeQuality_Analysis'!B:B,"HIGH") -> 3 | E34: =COUNTIFS('Bugs&CodeQuality_Analysis'!A:A,"*BUGS-MB*",'Bugs&CodeQuality_Analysis'!B:B,"MEDIUM") -> 4 | F34: =COUNTIFS('Bugs&CodeQuality_Analysis'!A:A,"*BUGS-MB*",'Bugs&CodeQuality_Analysis'!B:B,"LOW") -> 0 | G34: =SUM(C34:F34) -> 8
B35: Total | C35: =SUM(C29:C33) -> 11 | D35: =SUM(D29:D33) -> 39 | E35: =SUM(E29:E33) -> 41 | F35: =SUM(F29:F33) -> 34 | G35: =SUM(C35:F35) -> 125
B37: JTNY AWS Audit - Complete Analysis
C38: Critical | D38: High | E38: Medium | F38: Low | G38: Total
C39: =COUNTIFS(AWS_Audit!A:A,"*AWS*",AWS_Audit!B:B,"CRITICAL") -> 13 | D39: =COUNTIFS(AWS_Audit!A:A,"*AWS*",AWS_Audit!B:B,"HIGH") -> 10 | E39: =COUNTIFS(AWS_Audit!A:A,"*AWS*",AWS_Audit!B:B,"MEDIUM") -> 5 | F39: =COUNTIFS(AWS_Audit!A:A,"*AWS*",AWS_Audit!B:B,"LOW") -> 1 | G39: =SUM(C39:F39) -> 29
B41: Total findings | G41: =SUM(F3,G15,G25,G35,G39) -> 465

Sheet Security_Analysis
A1: SEITech | M1: JTNY | Q1: SEITech
A2: ID | B2: Severity | C2: Category | D2: Issue | E2: Location | F2: Description | G2: Impact | H2: OWASP | I2: CVE/CWE | J2: Log Date | K2: Estimate (WD) | L2: Milestone | M2: Investigation Result / Team Reply | N2: Status | O2: Responsible | P2: Date of Reply | Q2: Feedback | R2: Actions Required | S2: Date of Reply | T2: Customer Feedback
A3: SEC-001 | B3: CRITICAL | C3: Credentials | D3: Hardcoded MongoDB Credentials | E3: dashboard-backend/api/settings/dev.py:26-35; mobile-backend/api/settings/dev.py | F3: Database credentials exposed in plaintext in source code, allowing anyone with repo access to compromise the entire database | G3: Complete database compromise | H3: A07:2021 - Identification and Authentication Failures | I3: CWE-798 | J3: 45963 | K3: 3 | L3: 1 | M3: After investigation, this file (dev.py) is used only for local development with a local MongoDB instance. The staging and production servers use separate configuration files (stage.env and pro.env) with environment variables — no credentials are hardcoded there. Therefore, this finding does not pose a risk to the live environment. | N3: Not an Issue / Safe | O3: Backend Team | P3: 45964 | Q3: Still a risk. Credentials in git history are permanent. Anyone with repo access (current/former employees, contractors, stolen credentials) can extract these. If dev MongoDB is network-accessible, it's compromised. | R3: *Remove credentials from git history using BFG Repo-Cleaner *Rotate MongoDB credentials immediately (delete user 'tharwat', create new) *Migrate to environment variables in .env files *Add .env files to .gitignore *Implement pre-commit hooks to prevent future credential commits | S3: 45965 | T3: 5.11.2025, by Mahmoud Biltagy: Ammar Yasser will check if any credentials are still on repo and remove it
A4: SEC-002 | B4: CRITICAL | C4: Credentials | D4: Exposed AWS Access Keys | E4: mobile-backend/api/settings/base.py:137-140 | F4: AWS IAM credentials hardcoded, enabling unauthorized access to AWS services and potential massive billing charges | G4: AWS account compromise, financial loss | H4: A05:2021 - Security Misconfiguration | I4: CWE-798 | J4: 45963 | K4: 3 | L4: 1 | M4: After investigation, we confirm this is a valid issue. The AWS credentials exposed in the source code are used for the OTP mail service (AWS SES). These credentials should not be hardcoded and require immediate handling. | N4: Valid Issue – Needs Action | O4: Backend Team | P4: 45964 | R4: *Rotate AWS IAM credentials immediately in AWS Console *Review CloudTrail logs for unauthorized usage in past 90 days *Set up billing alerts and budget caps in AWS *Move credentials to environment variables *Implement AWS Secrets Manager for credential storage *Restrict IAM policy to minimum permissions (only SES:SendEmail) *Add IP restrictions if servers have static IPs | S4: 45965
A5: SEC-003 | B5: CRITICAL | C5: Credentials | D5: Firebase Cloud Messaging Token Exposed | E5: dashboard-backend/Modules/firebase.py:9; mobile-backend/Modules/firebase.py | F5: Server token hardcoded, allowing anyone to send unauthorized push notifications to all users for phishing/spam | G5: Phishing attacks, reputation damage | H5: A05:2021 - Security Misconfiguration | I5: CWE-798 | J5: 45963 | K5: 3 | L5: 1 | M5: After investigation, the issue is valid — the Firebase server token is hardcoded for testing push notifications. This token must be protected to prevent unauthorized use. | N5: Valid Issue – Needs Action | O5: Backend Team | P5: 45964 | R5: *Regenerate Firebase server key in Firebase Console *Move token to environment variables immediately *Review Firebase notification logs for abuse *Implement notification rate limiting (max 10 per user per hour) *Add notification logging with user ID, timestamp, and IP *Implement user notification preferences | S5: 45965
A6: SEC-004 | B6: CRITICAL | C6: Credentials | D6: Google Maps API Key Hardcoded | E6: mobile-passenger/lib/shared/constants/constants.dart; mobile-driver/lib/shared/constants/constants.dart | F6: API key easily extracted from APK, enabling quota exhaustion attacks and potentially thousands in Google Cloud charges | G6: Financial loss, service disruption | H6: A05:2021 - Security Misconfiguration | I6: CWE-798 | J6: 45963 | K6: 3 | L6: 1 | M6: After investigation, the API key is hardcoded. | N6: Valid Issue – Needs Action | O6: Mobile | P6: 45964 | R6: *Set up Google Cloud billing alerts IMMEDIATELY (critical) *Restrict all 3 API keys by application signatures (Android bundle ID, iOS bundle ID) *Set daily quota limits for each Maps API in Google Cloud Console *Enable detailed API usage monitoring *For sensitive operations, implement server-side proxy *Consider API key obfuscation in mobile apps *Monitor usage daily for 30 days after fix | S6: 45965
A7: SEC-005 | B7: CRITICAL | C7: Configuration | D7: Permissive CORS Configuration | E7: dashboard-backend/api/settings/base.py; mobile-backend/api/settings/base.py | F7: CORS_ORIGIN_ALLOW_ALL = True allows any website to make authenticated requests, enabling CSRF and data theft | G7: CSRF attacks, data theft | H7: A01:2021 - Broken Access Control | I7: CWE-942 | J7: 45963 | K7: 3 | L7: 1 | M7: The configuration was confirmed during review. CORS_ORIGIN_ALLOW_ALL = True is currently active and should be restricted to specific origins. | N7: Valid Issue – Needs Action | O7: Backend Team | P7: 45964 | R7: *Change CORS_ORIGIN_ALLOW_ALL from True to False *Set CORS_ALLOWED_ORIGINS to whitelist only production, staging, and localhost domains *Enable CORS_ALLOW_CREDENTIALS = True *Implement CSRF protection for state-changing operations *Test all frontend integrations after change *Add CORS verification to deployment checklist | S7: 45965
A8: SEC-006 | B8: CRITICAL | C8: Rate Limiting | D8: Ineffective Rate Limiting | E8: dashboard-backend/api/settings/base.py; mobile-backend/api/settings/base.py | F8: Extremely high limits (5000 req/sec) allow brute force attacks, OTP enumeration, and DoS attacks | G8: Account takeover, service disruption | H8: A04:2021 - Insecure Design | I8: CWE-307 | J8: 45963 | K8: 3 | L8: 1 | M8: After investigation, high limits (5000 req/sec) are configured in the staging environment for testing purposes. In production, current throttle limits (anon: 10/minute, user: 10/second) are active, and stricter rate-limiting configurations have been applied to ensure security. | N8: Needs Discussion | O8: Backend Team | P8: 45964 | Q8: Production limit still too high. 10 requests/second per user = 600/minute = 36,000/hour. This enables OTP brute force and abuse. Industry standard for ride-sharing apps: 10-50 requests/minute per user | R8: *Implement endpoint-specific throttling classes *Configure strict rate limits: OTP (3 per 15min), Login (5 per hour), Password reset (3 per hour), General API (100 per minute) *Add IP-based rate limiting for anonymous users *Implement progressive delays after failed attempts (exponential backoff) *Add CAPTCHA after 3 failed login attempts *Log all rate limit violations with IP and user info | S8: 45965
A9: SEC-007 | B9: HIGH | C9: Authentication | D9: Excessive Token Lifetime | E9: dashboard-backend/api/settings/base.py; mobile-backend/api/settings/base.py | F9: 7-day token validity and unlimited tokens per user extend exploitation window for stolen credentials | G9: Extended attack window | H9: A07:2021 - Identification and Authentication Failures | I9: CWE-613 | J9: 45963 | K9: 2 | L9: 1 | N9: Valid Issue – Needs Action | O9: Backend Team | P9: 45964 | R9: *Reduce access token lifetime to 15-60 minutes *Implement refresh tokens with 7-30 day lifetime *Create token refresh endpoint in backend *Store refresh tokens in database with device/IP tracking *Implement automatic token refresh in frontend before expiry *Add token revocation on password change and logout *Set TOKEN_LIMIT_PER_USER to reasonable limits (3 for passengers, 2 for drivers/admins) | S9: 45965
A10: SEC-008 | B10: HIGH | C10: Storage | D10: Authentication Tokens in localStorage | E10: dashboard-frontend/src/shared/apiCall/ApiCall.js; dashboard-frontend/src/components/Login.jsx | F10: Tokens stored in localStorage are vulnerable to XSS attacks for easy theft | G10: Token theft via XSS | H10: A03:2021 - Injection | I10: CWE-922 | J10: 45963 | K10: 2 | L10: 1 | M10: Thanks for this observation . You are right for sure. I researched the issue further and didn’t realize it could be that dangerous. It indeed exposes the app to potential XSS-based token theft. From my research, I learned that the best practice for stronger security is to use three tokens: access token, refresh token, and CSRF token to help prevent CSRF attacks and improve overall authentication safety. I really appreciate your detailed feedback and contributions. I have learnt a lot from this review sheet. Thanks and Regards . | N10: Valid Issue – Needs Action | O10: Frontend and Backend | P10: 45964 | R10: *Backend: Configure Knox to use httpOnly, secure, SameSite=Strict cookies *Backend: Store refresh tokens in separate httpOnly cookies *Backend: Implement CSRF token generation and validation *Frontend: Remove all localStorage.getItem/setItem for tokens *Frontend: Let browser handle cookies automatically *Frontend: Include CSRF token in request headers *Test authentication flow thoroughly across browsers | S10: 45965
A11: SEC-009 | B11: HIGH | C11: Authentication | D11: No Multi-Factor Authentication | E11: System-wide authentication flow | F11: Only password authentication makes accounts vulnerable to phishing, credential stuffing, and password reuse attacks | G11: Account takeover | H11: A07:2021 - Identification and Authentication Failures | I11: CWE-308 | J11: 45963 | K11: 3 | L11: 1 | M11: After investigation, MFA is not implemented in the system. | N11: Valid Issue – Needs Action | O11: Backend&mobile | P11: 45964 | R11: *Implement TOTP-based MFA using existing django-otp package *Support Google Authenticator, Authy, Microsoft Authenticator *Make MFA mandatory for: All admin accounts, Drivers with 100+ trips, Users with saved payment methods *Provide recovery codes (one-time use, printable) *Add SMS backup codes as alternative *Implement MFA reset flow with identity verification *Offer optional MFA for all other users | S11: 45965
A12: SEC-010 | B12: HIGH | C12: Dependencies | D12: Outdated Django Framework | E12: dashboard-backend/requirements.txt; mobile-backend/requirements.txt | F12: Django 4.0.3 has 15+ known CVEs including critical SQL injection (CVE-2023-31047) | G12: SQL injection, RCE | H12: A06:2021 - Vulnerable and Outdated Components | I12: CVE-2023-31047 | J12: 45963 | L12: 1 | M12: After investigation, the project uses the Djongo package for MongoDB integration, which currently supports only specific Django versions. Updating Django would break Djongo compatibility. | N12: Needs Discussion | O12: Backend Team | P12: 45964 | Q12: Running known-vulnerable Django is a compliance violation. Djongo incompatibility is not an acceptable excuse. | R12: I need more research to a better option. But for now I found 3 options: *(Django 5.0 + official backend) - IF all dependencies support Django 5.0 *Second Choice: (PostgreSQL) - Best long-term if Option 1 not viable *Third Choice: (PyMongo + Custom) - If must stay on MongoDB but can't do Option 1 | S12: 45965 | T12: 5.11.2025, by Mahmoud Biltagy: It will need a lot of effort, Jtny team will still research migration strategy to not break the system
A13: SEC-011 | B13: HIGH | C13: Headers | D13: Missing Security Headers | E13: dashboard-backend/api/settings/base.py; mobile-backend/api/settings/base.py | F13: No CSP, HSTS, X-Content-Type-Options, etc., leaving app vulnerable to XSS, MITM, and clickjacking | G13: XSS, clickjacking, MITM | H13: A05:2021 - Security Misconfiguration | I13: CWE-693 | J13: 45963 | K13: 3 | L13: 1 | M13: After investigation, several key security headers are missing (CSP, HSTS, X-Content-Type-Options). | N13: Valid Issue – Needs Action | O13: Backend Team | P13: 45964 | R13: *Install django-csp package *Add SecurityHeadersMiddleware to MIDDLEWARE *Configure headers: X-Content-Type-Options: nosniff, X-Frame-Options: DENY, Strict-Transport-Security (HSTS), Content-Security-Policy (CSP), X-XSS-Protection *Add SECURE_SSL_REDIRECT = True for production *Test headers using securityheaders.com *Run Django deployment check | S13: 45965
A14: SEC-012 | B14: HIGH | C14: Input Validation | D14: Insufficient Input Validation | E14: dashboard-backend/Transaction/models.py; dashboard-backend/Trip/serializers.py; mobile-backend/Account/serializers.py | F14: No validation/sanitization enables NoSQL injection, XSS, and data corruption | G14: Data injection attacks | H14: A03:2021 - Injection | I14: CWE-20 | J14: 45963 | K14: 3 | L14: 1 | N14: Needs Discussion | O14: gray | P14: 45964 | Q14: I believe it can be assigned to Backend Team. input validation is mandatory. | R14: *Audit all Django REST Framework serializers for validation *Implement field validators for all user inputs *Add input sanitization using bleach library for HTML/text fields *Implement MongoDB query parameter validation (prevent $where, $regex abuse) *Add string length limits on all CharField/TextField *Whitelist allowed characters for critical fields (usernames, IDs, phones) *Use Django's validators.RegexValidator for pattern matching | S14: 45965
A15: SEC-013 | B15: HIGH | C15: Authentication | D15: Excessive OTP Validity Period | E15: dashboard-backend/Account/models.py; mobile-backend/Account/models.py | F15: 7-minute OTP validity (line 1116) provides extended window for brute force and social engineering attacks | G15: OTP bypass attacks | H15: A07:2021 - Identification and Authentication Failures | I15: CWE-294 | J15: 45963 | K15: 2 | L15: 1 | N15: Needs Discussion | O15: gray | P15: 45964 | Q15: 7 minutes might be acceptable for UX, but needs validation. I believe it can be assigned to the Backend Team. | R15: *Review OTP expiry configuration in Account models *Consider reducing from 7 minutes to 5 minutes (industry standard for SMS) *CRITICAL: Implement OTP attempt limiting (maximum 3-5 attempts) *Add rate limiting on OTP generation (max 3 OTPs per 15 minutes per phone) *Implement progressive delays after failed OTP attempts *Add OTP failure logging and monitoring *Conduct UX testing to ensure 5 minutes is sufficient | S15: 45965
A16: SEC-014 | B16: HIGH | C16: Configuration | D16: Debug Mode Enabled | E16: dashboard-backend/api/settings/dev.py; mobile-backend/api/settings/dev.py | F16: DEBUG = True exposes stack traces, credentials, file paths, and system architecture in error messages | G16: Information disclosure | H16: A05:2021 - Security Misconfiguration | I16: CWE-489 | J16: 45963 | K16: 1 | L16: 1 | M16: After investigation, DEBUG = True is used only in the development configuration (dev.py) for testing endpoints locally. The production server is configured with DEBUG = False and managed through the pro.env file. Therefore, this configuration does not affect the live environment. | N16: Not an Issue / Safe | O16: Backend Team | P16: 45964 | Q16: Agree, not an issue if production is secure and properly configured. | S16: 45965
A17: SEC-015 | B17: HIGH | C17: Monitoring | D17: Insufficient Logging and Monitoring | E17: System-wide; dashboard-backend/api/settings/base.py | F17: Minimal logging prevents detection of breaches, attacks, and unauthorized access; violates GDPR/PCI-DSS | G17: Undetected breaches | H17: A09:2021 - Security Logging and Monitoring Failures | I17: CWE-778 | J17: 45963 | K17: 3 | L17: 1 | M17: After investigation, current logging is minimal and defaults to Django console. Recommended to implement structured logging for authentication events, API requests, and admin actions. | N17: Needs Discussion | O17: Backend Team | P17: 45964 | Q17: Logging is a compliance requirement. | R17: *Implement structured JSON logging using Python logging library *Log all authentication events: login success/failure, logout, password changes, MFA events *Log authorization failures (403 errors) *Log admin panel actions (user edits, role changes, permission grants) *Set up log aggregation (ELK Stack, CloudWatch Logs, or Datadog) *Configure alerts for suspicious patterns: multiple failed logins, unusual API access, admin actions outside business hours *Ensure logs include: timestamp, user ID, IP address, action, outcome *Set log retention policy (90 days minimum for compliance) | S17: 45965
A18: SEC-016 | B18: HIGH | C18: Infrastructure | D18: No Web Application Firewall | E18: Infrastructure level | F18: Direct API exposure with no DDoS protection, bot detection, or traffic filtering at edge | G18: DDoS, automated attacks | H18: A05:2021 - Security Misconfiguration | I18: CWE-693 | J18: 45963 | K18: 3 | L18: 1 | N18: Valid Issue – Needs Action | O18: security | P18: 45964 | R18: *Deploy Cloudflare Free tier IMMEDIATELY (takes 15-30 minutes, zero cost) *Point domain DNS to Cloudflare nameservers *Enable WAF rules and DDoS protection (automatic) *Configure SSL/TLS (Full or Strict mode) *Add basic rate limiting rules in Cloudflare *Enable bot fight mode *Set up alerts for traffic anomalies *Review analytics for attack patterns | S18: 45965
A19: SEC-017 | B19: HIGH | C19: Secrets Management | D19: No Secrets Management Solution | E19: System-wide deployment | F19: Secrets in plaintext .env files and environment variables with no rotation, encryption, or audit trail | G19: Credential exposure | H19: A05:2021 - Security Misconfiguration | I19: CWE-798 | J19: 45963 | K19: 2 | L19: 1 | O19: gray | P19: 45964 | Q19: Can be assigned to DevOps Team. | R19: *Quick win: Implement django-environ for .env file management *Ensure all .env files are in .gitignore *Choose secrets management solution: AWS Secrets Manager ($0.40/secret/month) OR HashiCorp Vault (free, self-hosted) *Migrate all credentials to secrets manager: MongoDB, AWS, Firebase, Google Maps, OAuth secrets, SMS credentials *Implement automatic secret rotation for databases *Add secrets access audit logging *Document secret rotation procedures | S19: 45965
A20: SEC-018 | B20: MEDIUM | C20: API Design | D20: No API Versioning | E20: System-wide API endpoints | F20: Breaking changes affect all clients simultaneously; no gradual migration path | G20: Service disruption | H20: A04:2021 - Insecure Design | I20: CWE-656 | J20: 45963 | K20: 1 | L20: 1 | N20: Not an Issue | O20: Backend Team | P20: 45964 | Q20: Low priority for security. This is an operational/DevOps concern, not a security vulnerability. API versioning is good practice but not urgent for security. | R20: *Not a security priority *Consider implementing when planning breaking API changes *Options: URL-based versioning (/api/v1/), Header-based versioning | S20: 45965
A21: SEC-019 | B21: MEDIUM | C21: Mobile Security | D21: No SSL Certificate Pinning | E21: mobile-passenger/lib/services/api_service.dart; mobile-driver/lib/services/api_service.dart | F21: Mobile apps vulnerable to MITM attacks on compromised networks | G21: MITM attacks | H21: A02:2021 - Cryptographic Failures | I21: CWE-295 | J21: 45963 | K21: 2 | L21: 1 | M21: After investigation, SSL certificate pinning is not implemented. | N21: Valid Issue – Needs Action | O21: Mobile | P21: 45964 | R21: *Research Flutter certificate pinning packages (dio with pinning, flutter_ssl_pinning) *Implement dual pinning: Pin primary certificate AND backup certificate *Extract SSL certificate from production server *Implement pinning in HTTP client initialization *Test with mitmproxy to verify MITM protection *CRITICAL: Implement certificate update mechanism (backend endpoint OR app update) *Plan for certificate expiry (certificates typically 1-2 years) *Document pin update procedures *Priority higher for driver app (location/financial data) | S21: 45965
A22: SEC-020 | B22: MEDIUM | C22: Mobile Security | D22: No Root/Jailbreak Detection | E22: Mobile Passenger App; Mobile Driver App | F22: Apps run on compromised devices, enabling keylogging, memory dumping, and code injection | G22: App tampering | H22: M8 - Code Tampering | I22: CWE-919 | J22: 45963 | K22: 3 | L22: 1 | M22: After investigation, apps currently lack root/jailbreak detection. | N22: Valid Issue – Needs Action | O22: Mobile | P22: 45964 | R22: *Research Flutter packages: flutter_jailbreak_detection or trust_fall (newer, better maintained) *Implement detection on app startup and periodically during use *Decision needed: Driver app - BLOCK on rooted devices (RECOMMENDED due to GPS spoofing risk), Passenger app - WARN user but allow *Implement SafetyNet Attestation API for Android *Implement DeviceCheck for iOS *Add graceful error messages for users *Log all jailbreak detection events | S22: 45965
A23: SEC-021 | B23: MEDIUM | C23: File Upload | D23: Insufficient File Upload Validation | E23: User profile uploads; driver documents | F23: No file type/size validation enables malicious file upload, storage exhaustion, and XSS via SVG | G23: XSS, storage exhaustion | H23: A03:2021 - Injection | I23: CWE-434 | J23: 45963 | K23: 2 | L23: 1 | M23: After investigation, file uploads do not enforce allowed types or size limits. Recommended to validate file type (e.g., images only), enforce max file size | N23: Valid Issue – Needs Action | O23: backend&front&mobile | P23: 45964 | R23: *Backend: Whitelist MIME types (image/jpeg, image/png for photos; add application/pdf for documents) *Backend: Validate magic bytes, NOT just file extension *Backend: Set max file sizes (5MB for profile photos, 10MB for documents) *Backend: Sanitize filenames (remove special characters, prevent path traversal) *Frontend: Client-side file type checking before upload (UX improvement) *Frontend: Show file size before upload *Storage: Store uploads OUTSIDE web root, generate random filenames, serve via signed URLs with expiration *Optional but recommended: Scan uploaded files with ClamAV for malware *Implement file upload rate limiting *Log all file uploads with user ID | S23: 45965
A24: SEC-022 | B24: MEDIUM | C24: Session Management | D24: Unlimited Concurrent Sessions | E24: dashboard-backend/api/settings/base.py; mobile-backend/api/settings/base.py | F24: TOKEN_LIMIT_PER_USER: None enables account sharing and makes token theft undetectable | G24: Account sharing | H24: A07:2021 - Identification and Authentication Failures | I24: CWE-384 | J24: 45963 | K24: 2 | L24: 1 | M24: After investigation, TOKEN_LIMIT_PER_USER is set to None allowing unlimited concurrent sessions. | N24: Valid Issue – Needs Action | O24: Backend Team | P24: 45964 | R24: *Set TOKEN_LIMIT_PER_USER to reasonable limits: Passengers (3 devices), Drivers (2 devices), Admins (2 devices) *Implement "Active Sessions" management view in user settings *Show session details: device info, last IP, last activity time, geolocation (optional) *Allow users to revoke sessions remotely *Send email notification when new device logs in *Track tokens in database with metadata: device_info, ip_address, created_at, last_activity *Auto-revoke oldest session when limit exceeded *Update Knox configuration for token tracking | S24: 45965
A25: SEC-023 | B25: MEDIUM | C25: Password Policy | D25: Weak Password Policy | E25: dashboard-backend/api/settings/base.py | F25: Default 8-char minimum with no complexity requirements allows weak passwords like 'password123' | G25: Weak passwords | H25: A07:2021 - Identification and Authentication Failures | I25: CWE-521 | J25: 45963 | K25: 1 | L25: 1 | M25: After investigation, the current password validators enforce only minimum length. Recommended to enforce complexity rules (uppercase, lowercase, number, symbol) and optionally integrate password blacklist. | N25: Valid Issue – Needs Action | O25: Backend&mobile | P25: 45964 | R25: *Keep existing 4 Django validators (they are good baseline) *Increase MinimumLengthValidator to 10-12 characters minimum *Configure CommonPasswordValidator with larger blacklist *Consider adding explicit complexity requirements OR use strength score *Implement password strength meter in frontend (zxcvbn.js library) *Optional: Check against Have I Been Pwned API for compromised passwords *Mobile apps: Implement identical validation *Mobile apps: Add visual password strength indicator | S25: 45965
A26: SEC-024 | B26: MEDIUM | C26: DoS Protection | D26: No Request Size Limits | E26: Django settings; web server configuration | F26: No limits on payload size enables memory exhaustion DoS via large JSON/file uploads | G26: DoS attacks | H26: A04:2021 - Insecure Design | I26: CWE-400 | J26: 45963 | K26: 2 | L26: 1 | M26: After investigation, there is no current limit on request size, which could allow memory exhaustion attacks. | N26: Valid Issue – Needs Action | O26: Backend Team | P26: 45964 | R26: *Django settings: Add DATA_UPLOAD_MAX_MEMORY_SIZE = 5242880 (5MB for API requests) *Django settings: Add FILE_UPLOAD_MAX_MEMORY_SIZE = 10485760 (10MB for file uploads) *Web server (nginx): Add client_max_body_size 10M; in server block *Web server (Apache): Add LimitRequestBody 10485760 in VirtualHost *Consider per-endpoint customization using Django middleware *Test limits by attempting large uploads *Ensure appropriate error messages are returned *Document limits for API consumers | S26: 45965
A27: SEC-025 | B27: MEDIUM | C27: Performance | D27: No Database Query Optimization | E27: Various views and serializers | F27: N+1 query problems cause database overload and enable DoS via slow queries | G27: Performance degradation | H27: A04:2021 - Insecure Design | I27: CWE-400 | J27: 45963 | K27: 2 | L27: 1 | M27: After investigation, several views and serializers exhibit N+1 query patterns, which could impact performance under high load. | N27: Needs Discussion | O27: Backend Team | P27: 45964 | Q27: This is a performance issue. N+1 queries impact scalability but are not a direct security vulnerability. | S27: 45965
A28: SEC-026 | B28: MEDIUM | C28: File Access | D28: No Content Security for Stored Files | E28: User-uploaded files; media storage | F28: Predictable URLs and no access control enable unauthorized document access and enumeration | G28: Data exposure | H28: A01:2021 - Broken Access Control | I28: CWE-639 | J28: 45963 | K28: 2 | L28: 1 | M28: After investigation, user-uploaded files are accessible via predictable URLs without access control. | N28: Needs Discussion | O28: Backend Team | P28: 45964 | Q28: Depends on file types. Security requirements differ by file type. Public files (profile pictures) don't need access control. Private files (driver licenses) absolutely do. We need to classify your files and design appropriate security for each category. | R28: *Classify all file types: PUBLIC (profile pictures, car photos) vs PRIVATE (driver licenses, insurance, tax docs) *For PUBLIC files: Current setup acceptable, consider CDN for performance *For PRIVATE files (CRITICAL): Store outside MEDIA_ROOT or use private S3 bucket, Create secure file serving view with permission checks, Generate signed URLs with short expiration (1-5 minutes), *Implement file access logging *Verify authorization: Drivers can only access their own documents, Admins can access all *Log all file access attempts: user_id, file_id, timestamp, IP, outcome *Consider watermarking sensitive documents *Consider document encryption at rest for highly sensitive files | S28: 45965

Sheet Performance_Summary
A1: JTNY Performance Audit - Complete Analysis | H1: Estimated Performance Improvements
A2: Repository | B2: Critical | C2: High | D2: Medium | E2: Low | F2: Total | H2: Optimization | I2: Expected Improvement | J2: User Experience Impact
A3: DB | B3: =COUNTIFS(Performance_Analysis!A:A,"*PERF-DB*",Performance_Analysis!B:B,"CRITICAL") -> 6 | C3: =COUNTIFS(Performance_Analysis!A:A,"*PERF-DB*",Performance_Analysis!B:B,"HIGH") -> 9 | D3: =COUNTIFS(Performance_Analysis!A:A,"*PERF-DB*",Performance_Analysis!B:B,"MEDIUM") -> 12 | E3: =COUNTIFS(Performance_Analysis!A:A,"*PERF-DB*",Performance_Analysis!B:B,"LOW") -> 4 | F3: =SUM(B3:E3) -> 31 | H3: Mobile App Startup | I3: 400-1200ms → 100-300ms (70-92% faster) | J3: App opens in under 1s
A4: MB | B4: =COUNTIFS(Performance_Analysis!A:A,"*PERF-MB*",Performance_Analysis!B:B,"CRITICAL") -> 2 | C4: =COUNTIFS(Performance_Analysis!A:A,"*PERF-MB*",Performance_Analysis!B:B,"HIGH") -> 7 | D4: =COUNTIFS(Performance_Analysis!A:A,"*PERF-MB*",Performance_Analysis!B:B,"MEDIUM") -> 6 | E4: =COUNTIFS(Performance_Analysis!A:A,"*PERF-MB*",Performance_Analysis!B:B,"LOW") -> 0 | F4: =SUM(B4:E4) -> 15 | H4: Database Query Optimization | I4: 70-85% faster queries | J4: Page loads under 2s
A5: DF | B5: =COUNTIFS(Performance_Analysis!A:A,"*PERF-DF*",Performance_Analysis!B:B,"CRITICAL") -> 2 | C5: =COUNTIFS(Performance_Analysis!A:A,"*PERF-DF*",Performance_Analysis!B:B,"HIGH") -> 8 | D5: =COUNTIFS(Performance_Analysis!A:A,"*PERF-DF*",Performance_Analysis!B:B,"MEDIUM") -> 4 | E5: =COUNTIFS(Performance_Analysis!A:A,"*PERF-DF*",Performance_Analysis!B:B,"LOW") -> 1 | F5: =SUM(B5:E5) -> 15 | H5: HTTP Client Configuration | I5: 100-300ms → 10-30ms per request (70-90% faster) | J5: Instant API responses
A6: MP | B6: =COUNTIFS(Performance_Analysis!A:A,"*PERF-MP*",Performance_Analysis!B:B,"CRITICAL") -> 1 | C6: =COUNTIFS(Performance_Analysis!A:A,"*PERF-MP*",Performance_Analysis!B:B,"HIGH") -> 7 | D6: =COUNTIFS(Performance_Analysis!A:A,"*PERF-MP*",Performance_Analysis!B:B,"MEDIUM") -> 6 | E6: =COUNTIFS(Performance_Analysis!A:A,"*PERF-MP*",Performance_Analysis!B:B,"LOW") -> 0 | F6: =SUM(B6:E6) -> 14 | H6: Location Tracking (Driver App) | I6: 15-30% → 3-5% battery drain (80-90% reduction) | J6: All-day usage for drivers
A7: MD | B7: =COUNTIFS(Performance_Analysis!A:A,"*PERF-MD*",Performance_Analysis!B:B,"CRITICAL") -> 2 | C7: =COUNTIFS(Performance_Analysis!A:A,"*PERF-MD*",Performance_Analysis!B:B,"HIGH") -> 7 | D7: =COUNTIFS(Performance_Analysis!A:A,"*PERF-MD*",Performance_Analysis!B:B,"MEDIUM") -> 5 | E7: =COUNTIFS(Performance_Analysis!A:A,"*PERF-MD*",Performance_Analysis!B:B,"LOW") -> 1 | F7: =SUM(B7:E7) -> 15 | H7: Provider Selective Rebuilds | I7: 100-500ms → 10-30ms updates (80-95% faster) | J7: Smooth 60 FPS animations
A8: SA | B8: =COUNTIFS(Performance_Analysis!A:A,"*PERF-SA*",Performance_Analysis!B:B,"CRITICAL") -> 2 | C8: =COUNTIFS(Performance_Analysis!A:A,"*PERF-SA*",Performance_Analysis!B:B,"HIGH") -> 4 | D8: =COUNTIFS(Performance_Analysis!A:A,"*PERF-SA*",Performance_Analysis!B:B,"MEDIUM") -> 3 | E8: =COUNTIFS(Performance_Analysis!A:A,"*PERF-SA*",Performance_Analysis!B:B,"LOW") -> 3 | F8: =SUM(B8:E8) -> 12 | H8: Trip History Pagination | I8: 2-5s → 200-500ms load (75-90% faster) | J8: Instant scrolling, no crashes
A9: CR | B9: =COUNTIFS(Performance_Analysis!A:A,"*PERF-CR*",Performance_Analysis!B:B,"CRITICAL") -> 2 | C9: =COUNTIFS(Performance_Analysis!A:A,"*PERF-CR*",Performance_Analysis!B:B,"HIGH") -> 2 | D9: =COUNTIFS(Performance_Analysis!A:A,"*PERF-CR*",Performance_Analysis!B:B,"MEDIUM") -> 2 | E9: =COUNTIFS(Performance_Analysis!A:A,"*PERF-CR*",Performance_Analysis!B:B,"LOW") -> 1 | F9: =SUM(B9:E9) -> 7 | H9: Firestore Persistence Disabled | I9: 200-1000ms → 50-150ms first query (70-85% faster) | J9: Fresh data instantly
A10: NTH | B10: =COUNTIFS(Performance_Analysis!A:A,"*PERF-NTH*",Performance_Analysis!B:B,"CRITICAL") -> 0 | C10: =COUNTIFS(Performance_Analysis!A:A,"*PERF-NTH*",Performance_Analysis!B:B,"HIGH") -> 0 | D10: =COUNTIFS(Performance_Analysis!A:A,"*PERF-NTH*",Performance_Analysis!B:B,"MEDIUM") -> 0 | E10: =COUNTIFS(Performance_Analysis!A:A,"*PERF-NTH*",Performance_Analysis!B:B,"LOW") -> 10 | F10: =SUM(B10:E10) -> 10 | H10: Request Debouncing | I10: 70-90% reduction in API calls | J10: No lag, reduced server load
A11: TOTAL | B11: =SUM(B3:B10) -> 17 | C11: =SUM(C3:C10) -> 44 | D11: =SUM(D3:D10) -> 38 | E11: =SUM(E3:E10) -> 20 | F11: =SUM(B11:E11) -> 119 | H11: Bundle Size Optimization | I11: 50% smaller JavaScript bundles | J11: 3s faster initial page load
H12: Image Optimization | I12: 60-80% smaller images | J12: Faster page rendering
H13: Real-time Connection Pool | I13: 40-60% reduction in connections | J13: Reduced infrastructure costs
H14: Lazy Loading Maps | I14: 300-800ms → 0ms at startup (100% eliminated) | J14: Instant app launch
H15: HTTP/2 Implementation | I15: 10-20% faster initial load | J15: Reduced latency globally
H16: CDN for Static Assets | I16: 200-500ms faster globally | J16: Better international UX
H17: Database Read Replicas | I17: 40-60% improvement in reads | J17: Faster analytics & reports
H18: APM Tool Integration | I18: Real-time monitoring | J18: Proactive issue resolution
H19: Load Testing Pipeline | I19: Prevents production crashes | J19: Stable during viral growth
H20: Performance Budgets | I20: Prevents regressions | J20: Consistent fast experience
H21: Chat HTML Rendering | I21: 30-45 FPS → 60 FPS scrolling (30-100% improvement) | J21: Smooth chat scrolling
H22: Memory Leak Fixes | I22: 80% reduction in crashes | J22: Stable long sessions

Sheet Performance_Analysis
A1: SEITech | M1: JTNY | Q1: SEITech
A2: ID | B2: Severity | C2: Category | D2: Issue | E2: Location | F2: Description | G2: Impact | H2: Actions Required | I2: Standards/Guidelines Followed | J2: Log Date | K2: Estimation (WD) | L2: Milestone | M2: Investigation Result / Team Reply | N2: Status | O2: Responsible | P2: Date of Reply | Q2: Feedback | R2: Date of Reply | S2: Customer Feedback
A3: PERF-DB-001 | B3: MEDIUM | C3: Database | D3: No Database Query Optimization | E3: Various views and serializers | F3: N+1 query problems cause database overload and enable DoS via slow queries | G3: *Performance degradation under load *Multiple queries where one would suffice *Database becomes bottleneck *Poor scalability | H3: *Rewrite ORM usage to leverage select_related/prefetch_related and collapse query counts. *Add a regression test that asserts query count for the affected endpoint. *Profile the affected queries with the database profiler to capture baseline timings. *Audit indexes and execution plans, adding or adjusting indexes to support the hot path. *Enable slow-query logging and surface metrics in the APM dashboard. | I3: OWASP API Security Top 10 (API4:2023 - Unrestricted Resource Consumption); CWE-1073; Performance Best Practices | J3: 45966 | K3: 2 | L3: 6 | M3: After investigation, several views and serializers exhibit N+1 query patterns, which could impact performance under high load. | N3: Needs Discussion | O3: Backend Team | P3: 45964 | Q3: This is both a performance and security issue. N+1 queries don't just slow down your application—they create a DoS vulnerability. An attacker can repeatedly call endpoints with N+1 problems to exhaust database connections. | R3: 45965
A4: PERF-DB-002 | B4: CRITICAL | C4: Database | D4: Missing Database Connection Pooling | E4: api/settings/prod.py:27-36 | F4: No connection pooling configured for MongoDB/Djongo. Missing maxPoolSize, minPoolSize configuration. | G4: *Each request creates new connections *Connection exhaustion under load *500-1000ms latency per request *Database becomes overwhelmed with connection overhead | H4: *Configure database connection pooling values (min/max pool size, timeouts) in production settings. *Validate pooled connection reuse under load with a staging load test. *Profile the affected queries with the database profiler to capture baseline timings. *Audit indexes and execution plans, adding or adjusting indexes to support the hot path. *Enable slow-query logging and surface metrics in the APM dashboard. | I4: OWASP API Security Top 10 (API4:2023); CWE-400; Database Performance Standards | J4: 45963 | K4: 5 | L4: 3
A5: PERF-DB-003 | B5: CRITICAL | C5: Database | D5: N+1 Query in Account Serializer | E5: Account/serializers.py:83-89 | F5: get_permissions() iterates through groups.all() then permissions.all() for each group. No prefetch_related. | G5: *User with 5 groups + 10 permissions each = 55 queries instead of 1 *Adds 200-500ms per user serialization *Authentication/authorization endpoints severely slowed *Every API call potentially affected | H5: *Rewrite ORM usage to leverage select_related/prefetch_related and collapse query counts. *Add a regression test that asserts query count for the affected endpoint. *Profile the affected queries with the database profiler to capture baseline timings. *Audit indexes and execution plans, adding or adjusting indexes to support the hot path. *Enable slow-query logging and surface metrics in the APM dashboard. | I5: ORM Performance Best Practices; CWE-1073 | J5: 45963 | K5: 4 | L5: 3
A6: PERF-DB-004 | B6: CRITICAL | C6: General | D6: Massive Aggregation Without Pagination | E6: Trip/models.py:787-1451 | F6: 1450+ line aggregation pipeline with 15+ $lookup stages. No result limiting. | G6: *Fetches thousands of trips at once *Memory issues (OOM killer can terminate process) *5-10 second response times *Server crashes under concurrent load *Database CPU at 100% | H6: *Break large aggregation pipelines into optimized stages with early filtering. *Add covering indexes for fields referenced in $match/$lookup steps. *Implement server-side pagination with deterministic ordering and limits. *Expose pagination parameters to clients and document defaults. *Use memory profiling tools to identify retained objects and fix leaks. | I6: OWASP API4:2023; CWE-770; Database Performance Standards | J6: 45963 | K6: 3 | L6: 3
A7: PERF-DB-005 | B7: CRITICAL | C7: General | D7: Inefficient Driver Pagination | E7: Driver/views.py:81-306 | F7: Multiple $lookup operations without indexed fields. Fetches all data then paginates in Python. | G7: *Loads 10,000 drivers into memory before pagination *2-5 second response time *High memory consumption *Database does all work, pagination happens in application *Scalability nightmare | H7: *Break large aggregation pipelines into optimized stages with early filtering. *Add covering indexes for fields referenced in $match/$lookup steps. *Implement server-side pagination with deterministic ordering and limits. *Expose pagination parameters to clients and document defaults. *Use memory profiling tools to identify retained objects and fix leaks. | I7: API Performance Standards; Pagination Best Practices | J7: 45963 | K7: 3 | L7: 3
A8: PERF-DB-006 | B8: CRITICAL | C8: Caching | D8: Missing Caching Layer | E8: Entire codebase - no cache configuration | F8: No Redis/Memcached configured. No caching for queries, sessions, permissions, config. | G8: *Every request hits database *100-300ms wasted per request *Database becomes bottleneck *Cannot scale horizontally *Repeated computation of same data | H8: *Select the appropriate cache backend (Redis/Memcached) and integrate with the service. *Define cache invalidation triggers tied to data mutations. *Introduce a centralized cache (Redis/Memcached) for expensive lookups with clear TTL guidance. *Design a cache invalidation strategy and attach cache busting to the relevant signals. *Add cache hit/miss metrics and alerts to detect regressions. | I8: Performance Best Practices; Caching Standards | J8: 45963 | K8: 5 | L8: 3
A9: PERF-DB-007 | B9: HIGH | C9: API | D9: Synchronous File Upload in Request | E9: Account/views.py:590-637 | F9: File uploads and Firebase operations done synchronously in request/response cycle. | G9: *User waits for file I/O and Firebase operations *500-2000ms blocking time per upload *Request threads blocked during upload *Poor scalability | H9: *Handle file uploads asynchronously and use pre-signed URLs to offload work from the API. *Scan and store uploads outside of the web tier to keep requests lightweight. *Batch Firebase calls and reuse initialized clients to reduce latency. *Monitor push notification delivery SLAs after the fix. *Remove synchronous heavy lifting from the request cycle or offload it to background workers. | I9: Asynchronous Processing Best Practices; CWE-400 | J9: 45963 | K9: 2 | L9: 4
A10: PERF-DB-008 | B10: HIGH | C10: General | D10: No Celery for Heavy Operations | E10: Multiple views | F10: SMS sending, Firebase updates, Excel generation done synchronously. | G10: *Excel generation takes 3-10 seconds blocking user *Email sending blocks requests *Push notifications delay responses *Poor user experience | H10: *Introduce a resilient task queue (Celery/RQ) for heavy background operations. *Ensure jobs are idempotent and include retry/backoff policies. *Stream large Excel exports instead of loading everything into memory. *Move export generation to a background worker and notify the user when ready. *Batch Firebase calls and reuse initialized clients to reduce latency. | I10: Background Processing Standards; Task Queue Best Practices | J10: 45963 | K10: 2 | L10: 4
A11: PERF-DB-009 | B11: HIGH | C11: Memory | D11: Excel Export Loads All Data Into Memory | E11: Driver/views.py:1243-1318 | F11: Fetches all records, loads into DataFrame, generates Excel. No streaming. | G11: *50,000 drivers = 500MB+ RAM per request *10-30 seconds generation time *Potential Out of Memory (OOM) errors *Server crashes under concurrent exports | H11: *Stream large Excel exports instead of loading everything into memory. *Move export generation to a background worker and notify the user when ready. *Use memory profiling tools to identify retained objects and fix leaks. *Add guardrails and alarms on process RSS to catch regressions. *Stream large datasets instead of materializing them in memory at once. | I11: Memory Management; CWE-400 | J11: 45963 | K11: 2 | L11: 4
A12: PERF-DB-010 | B12: HIGH | C12: Database | D12: Missing Query Optimization (only/defer) | E12: Account/views.py:478, 494-499 | F12: Queries fetch all model fields when only specific fields needed. | G12: *Fetching 20 fields instead of 5 needed *2-3x more data transfer from database *Slower serialization *Higher memory usage | H12: *Profile the affected queries with the database profiler to capture baseline timings. *Audit indexes and execution plans, adding or adjusting indexes to support the hot path. *Enable slow-query logging and surface metrics in the APM dashboard. *Capture before/after performance metrics (latency, throughput, resource usage) to validate the improvement. *Update documentation and runbooks with remediation details and rollback steps. | I12: ORM Performance Best Practices; Django Framework Guidelines | J12: 45963 | K12: 2 | L12: 4
A13: PERF-DB-011 | B13: HIGH | C13: Database | D13: Inefficient Nested Loops Over QuerySets | E13: Driver/views.py:814-832 | F13: Python loop over queryset calling function for each trip individually. | G13: *1000 trips = 1000 function calls instead of 1 aggregation *5-10 seconds vs 100ms *O(n) complexity where O(1) is possible *Database hammered with queries | H13: *Break large aggregation pipelines into optimized stages with early filtering. *Add covering indexes for fields referenced in $match/$lookup steps. *Profile the affected queries with the database profiler to capture baseline timings. *Audit indexes and execution plans, adding or adjusting indexes to support the hot path. *Enable slow-query logging and surface metrics in the APM dashboard. | I13: Algorithm Efficiency Standards; CWE-1050 | J13: 45963 | K13: 3 | L13: 4
A14: PERF-DB-012 | B14: HIGH | C14: General | D14: Complex Aggregation Pipeline | E14: Driver/models.py:555-928 | F14: 20+ stage aggregation with 13 $lookup, 8 $unwind. No verified indexes. | G14: *Each unindexed lookup is O(n*m) *1000 trips = 3-8 seconds per query *Database CPU at 100% *Concurrent queries cause timeouts | H14: *Break large aggregation pipelines into optimized stages with early filtering. *Add covering indexes for fields referenced in $match/$lookup steps. *Break the work into smaller batches or streaming chunks to avoid blocking the main thread. *Instrument the endpoint with detailed latency and throughput metrics. *Review error budgets and update runbooks with the remediation procedure. | I14: Database Performance Standards; MongoDB Best Practices | J14: 45963 | K14: 2 | L14: 4
